Workbook

Sheet Overview
A1: The Second Spark: card list
A2: Numbers follow the physical game (read from the Tabletop Simulator sheets). Names, wording and art are original to The Second Spark.
A4: Deck | B4: Cards | C4: Where it is used
A5: Cemetery cadavers | B5: =COUNTIF(Cadavers!B:B,"Cemetery") -> 14 | C5: Cemetery (hidden, draw 3)
A6: Morgue cadavers | B6: =COUNTIF(Cadavers!B:B,"Morgue") -> 14 | C6: Morgue (hidden, draw 2)
A7: Hospital cadavers | B7: =COUNTIF(Cadavers!B:B,"Hospital") -> 14 | C7: Hospital (2 face up), Hospital Thief
A8: Public Square cadavers | B8: =COUNTIF(Cadavers!B:B,"Public Square") -> 10 | C8: Public Square after executions
A9: Scoundrels | B9: =COUNTA(Scoundrels!A:A)-2 -> 16 | C9: Docks (3 face up)
A10: Research | B10: =COUNTA(Research!A:A)-2 -> 16 | C10: Academy (3 face up)
A11: Humanity | B11: =COUNTA(Humanity!A:A)-2 -> 16 | C11: Saint-Roch (3 face up)
A12: Events | B12: =COUNTA(Events!A:A)-2 -> 19 | C12: Event phase
A13: Encounters | B13: =COUNTA(Encounters!A:A)-2 -> 15 | C13: Event phase (4 per game)
A14: Characters | B14: =COUNTA(Characters!A:A)-2 -> 6 | C14: Title screen
A15: Total cards | B15: =SUM(B5:B14) -> 140
A17: Every card sheet ends with a ready-to-paste Prompt, a Negative prompt, the Aspect and the File name. Prompts are built from the Style sheet: edit a style there and all prompts update.

Sheet Style
A1: Prompt building blocks (prompts on every sheet = subject + style + format)
A2: Style: standard | B2: Dark hand-drawn coloured-pencil illustration on black-toned paper. Visible pencil strokes and cross-hatching, waxy layered colour, soft grain of the paper showing through. Gothic 1819 Paris, Mary Shelley mood. Low-key candlelit lighting: a single warm light source (candle, lantern or lamp) carving figures out of near-black shadow. Muted palette of soot black, bruised plum, oxblood red, tarnished brass and bone white, with one small accent of cold galvanic blue where electricity or life appears. Subtle vignette fading to black at the edges. Melancholic, unsettling, quietly beautiful rather than gory: wounds and death are suggested with restraint, never graphic. Hand-made imperfections, no digital gloss.
A3: Style: cadavers (visceral) | B3: Dark hand-drawn coloured-pencil illustration on black-toned paper. Visible pencil strokes and dense cross-hatching, waxy layered colour, soft grain of the paper showing through. Gothic 1819 Paris anatomical horror, Mary Shelley mood. Even darker than daylight allows: the body emerges from deep black, lit hard from one side by a single lantern. Visceral and unflinching: decaying flesh built up in waxy layers of grey-green, livid purple, jaundiced yellow and clotted oxblood; raw wounds, torn stitches, split skin, exposed bone and sinew where the body is broken; flies and grave dirt where it fits. Rendered with the cold precision of an anatomist's study, not cartoon splatter. No blue anywhere: these bodies have no spark of life. Hand-made imperfections, no digital gloss.
A4: Negative: standard | B4: text, letters, words, captions, logos, watermark, signature, card frame, border, UI, photorealistic, 3D render, CGI, glossy, airbrushed, smooth digital painting, anime, cartoon, chibi, bright saturated colours, daylight, white background, gore, exposed organs in detail, modern clothing, modern objects
A5: Negative: cadavers | B5: text, letters, words, captions, logos, watermark, signature, card frame, border, UI, photorealistic, 3D render, CGI, glossy, airbrushed, smooth digital painting, anime, cartoon, comic-book gore, paint-splatter blood, bright saturated red, daylight, white background, modern clothing, modern objects, blue light, living expression, open smiling eyes
A6: Format: portrait | B6: Format: 2:3 portrait, head and shoulders, centred, lower 20% dark and simple.
A7: Format: cadaver | B7: Format: 2:3 portrait, the body seen from above as it lies, head and upper torso, centred, lower 20% dark and simple.
A8: Format: wide | B8: Format: 16:9 landscape, wide establishing view of the place at night, small figures at most.
A9: Format: object | B9: Format: 4:3 landscape, one clear object or moment in close-up, simple dark background.

Sheet Cadavers
A1: Numbers follow the physical game (read from the Tabletop Simulator sheets). Names, wording and art are original to The Second Spark.
A2: Card | B2: Deck | C2: Stage | D2: Muscle | E2: Organ | F2: Blood | G2: Bone | H2: Total materials | I2: Expertise option | J2: Humanity cost | K2: Extra francs | L2: Notes | M2: Illustration subject | N2: Prompt (ready to paste) | O2: Negative prompt | P2: Aspect | Q2: File name
A3: Cemetery 01 | B3: Cemetery | C3: IV | D3: 0 | E3: 3 | F3: 0 | G3: 3 | H3: =SUM(D3:G3) -> 6 | I3: 1 | J3: 0 | M3: An elderly washerwoman in a collapsed pine coffin, sunken eye sockets, grave dirt in her grey hair, freshly dug up by lantern light, grave dirt and roots around, months in the ground, flesh shrunken and blackened, skin parchment-thin and torn, teeth bared | N3: =M3&". "&Style!$B$3&" "&Style!$B$7 -> An elderly washerwoman in a collapsed pine coffin, sunken eye sockets, grave dirt in her grey hair, freshly dug up by lantern light, grave dirt and roots around, months in the ground, flesh shrunken and blackened, skin parchment-thin and torn, teeth bared. Dark hand-drawn coloured-pencil illustration on black-toned paper. Visible pencil strokes and dense cross-hatching, waxy layered colour, soft grain of the paper showing through. Gothic 1819 Paris anatomical horror, Mary Shelley mood. Even darker than daylight allows: the body emerges from deep black, lit hard from one side by a single lantern. Visceral and unflinching: decaying flesh built up in waxy layers of grey-green, livid purple, jaundiced yellow and clotted oxblood; raw wounds, torn stitches, split skin, exposed bone and sinew where the body is broken; flies and grave dirt where it fits. Rendered with the cold precision of an anatomist's study, not cartoon splatter. No blue anywhere: these bodies have no spark of life. Hand-made imperfections, no digital gloss. Format: 2:3 portrait, the body seen from above as it lies, head and upper torso, centred, lower 20% dark and simple. | O3: =Style!$B$5 -> text, letters, words, captions, logos, watermark, signature, card frame, border, UI, photorealistic, 3D render, CGI, glossy, airbrushed, smooth digital painting, anime, cartoon, comic-book gore, paint-splatter blood, bright saturated red, daylight, white background, modern clothing, modern objects, blue light, living expression, open smiling eyes | P3: 2:3 | Q3: cemetery-01.png
A4: Cemetery 02 | B4: Cemetery | C4: IV | D4: 2 | E4: 2 | F4: 0 | G4: 3 | H4: =SUM(D4:G4) -> 7 | I4: 1 | J4: 0 | M4: A middle-aged stonemason, jaw slack and fallen open, burial shirt stained black with fluids, freshly dug up by lantern light, grave dirt and roots around, months in the ground, flesh shrunken and blackened, skin parchment-thin and torn, teeth bared | N4: =M4&". "&Style!$B$3&" "&Style!$B$7 -> A middle-aged stonemason, jaw slack and fallen open, burial shirt stained black with fluids, freshly dug up by lantern light, grave dirt and roots around, months in the ground, flesh shrunken and blackened, skin parchment-thin and torn, teeth bared. Dark hand-drawn coloured-pencil illustration on black-toned paper. Visible pencil strokes and dense cross-hatching, waxy layered colour, soft grain of the paper showing through. Gothic 1819 Paris anatomical horror, Mary Shelley mood. Even darker than daylight allows: the body emerges from deep black, lit hard from one side by a single lantern. Visceral and unflinching: decaying flesh built up in waxy layers of grey-green, livid purple, jaundiced yellow and clotted oxblood; raw wounds, torn stitches, split skin, exposed bone and sinew where the body is broken; flies and grave dirt where it fits. Rendered with the cold precision of an anatomist's study, not cartoon splatter. No blue anywhere: these bodies have no spark of life. Hand-made imperfections, no digital gloss. Format: 2:3 portrait, the body seen from above as it lies, head and upper torso, centred, lower 20% dark and simple. | O4: =Style!$B$5 -> text, letters, words, captions, logos, watermark, signature, card frame, border, UI, photorealistic, 3D render, CGI, glossy, airbrushed, smooth digital painting, anime, cartoon, comic-book gore, paint-splatter blood, bright saturated red, daylight, white background, modern clothing, modern objects, blue light, living expression, open smiling eyes | P4: 2:3 | Q4: cemetery-02.png
A5: Cemetery 03 | B5: Cemetery | C5: IV | D5: 2 | E5: 2 | F5: 0 | G5: 2 | H5: =SUM(D5:G5) -> 6 | I5: 1 | J5: 0 | M5: A young conscript of the Grande Armée in a rotting uniform, a sabre scar across his cheek split wide, freshly dug up by lantern light, grave dirt and roots around, months in the ground, flesh shrunken and blackened, skin parchment-thin and torn, teeth bared | N5: =M5&". "&Style!$B$3&" "&Style!$B$7 -> A young conscript of the Grande Armée in a rotting uniform, a sabre scar across his cheek split wide, freshly dug up by lantern light, grave dirt and roots around, months in the ground, flesh shrunken and blackened, skin parchment-thin and torn, teeth bared. Dark hand-drawn coloured-pencil illustration on black-toned paper. Visible pencil strokes and dense cross-hatching, waxy layered colour, soft grain of the paper showing through. Gothic 1819 Paris anatomical horror, Mary Shelley mood. Even darker than daylight allows: the body emerges from deep black, lit hard from one side by a single lantern. Visceral and unflinching: decaying flesh built up in waxy layers of grey-green, livid purple, jaundiced yellow and clotted oxblood; raw wounds, torn stitches, split skin, exposed bone and sinew where the body is broken; flies and grave dirt where it fits. Rendered with the cold precision of an anatomist's study, not cartoon splatter. No blue anywhere: these bodies have no spark of life. Hand-made imperfections, no digital gloss. Format: 2:3 portrait, the body seen from above as it lies, head and upper torso, centred, lower 20% dark and simple. | O5: =Style!$B$5 -> text, letters, words, captions, logos, watermark, signature, card frame, border, UI, photorealistic, 3D render, CGI, glossy, airbrushed, smooth digital painting, anime, cartoon, comic-book gore, paint-splatter blood, bright saturated red, daylight, white background, modern clothing, modern objects, blue light, living expression, open smiling eyes | P5: 2:3 | Q5: cemetery-03.png
A6: Cemetery 04 | B6: Cemetery | C6: IV | D6: 2 | E6: 1 | F6: 0 | G6: 3 | H6: =SUM(D6:G6) -> 6 | I6: 1 | J6: 0 | M6: A stout innkeeper in a burst burial suit, belly collapsed, beetles in the folds of cloth, freshly dug up by lantern light, grave dirt and roots around, months in the ground, flesh shrunken and blackened, skin parchment-thin and torn, teeth bared | N6: =M6&". "&Style!$B$3&" "&Style!$B$7 -> A stout innkeeper in a burst burial suit, belly collapsed, beetles in the folds of cloth, freshly dug up by lantern light, grave dirt and roots around, months in the ground, flesh shrunken and blackened, skin parchment-thin and torn, teeth bared. Dark hand-drawn coloured-pencil illustration on black-toned paper. Visible pencil strokes and dense cross-hatching, waxy layered colour, soft grain of the paper showing through. Gothic 1819 Paris anatomical horror, Mary Shelley mood. Even darker than daylight allows: the body emerges from deep black, lit hard from one side by a single lantern. Visceral and unflinching: decaying flesh built up in waxy layers of grey-green, livid purple, jaundiced yellow and clotted oxblood; raw wounds, torn stitches, split skin, exposed bone and sinew where the body is broken; flies and grave dirt where it fits. Rendered with the cold precision of an anatomist's study, not cartoon splatter. No blue anywhere: these bodies have no spark of life. Hand-made imperfections, no digital gloss. Format: 2:3 portrait, the body seen from above as it lies, head and upper torso, centred, lower 20% dark and simple. | O6: =Style!$B$5 -> text, letters, words, captions, logos, watermark, signature, card frame, border, UI, photorealistic, 3D render, CGI, glossy, airbrushed, smooth digital painting, anime, cartoon, comic-book gore, paint-splatter blood, bright saturated red, daylight, white background, modern clothing, modern objects, blue light, living expression, open smiling eyes | P6: 2:3 | Q6: cemetery-04.png
A7: Cemetery 05 | B7: Cemetery | C7: bones | D7: 0 | E7: 0 | F7: 0 | G7: 5 | H7: =SUM(D7:G7) -> 5 | I7: 0 | J7: 0 | L7: Bones only | M7: A jumble of brown bones and a cracked skull in a collapsed coffin, roots growing through the ribs, a few strands of hair and rags of skin still clinging | N7: =M7&". "&Style!$B$3&" "&Style!$B$7 -> A jumble of brown bones and a cracked skull in a collapsed coffin, roots growing through the ribs, a few strands of hair and rags of skin still clinging. Dark hand-drawn coloured-pencil illustration on black-toned paper. Visible pencil strokes and dense cross-hatching, waxy layered colour, soft grain of the paper showing through. Gothic 1819 Paris anatomical horror, Mary Shelley mood. Even darker than daylight allows: the body emerges from deep black, lit hard from one side by a single lantern. Visceral and unflinching: decaying flesh built up in waxy layers of grey-green, livid purple, jaundiced yellow and clotted oxblood; raw wounds, torn stitches, split skin, exposed bone and sinew where the body is broken; flies and grave dirt where it fits. Rendered with the cold precision of an anatomist's study, not cartoon splatter. No blue anywhere: these bodies have no spark of life. Hand-made imperfections, no digital gloss. Format: 2:3 portrait, the body seen from above as it lies, head and upper torso, centred, lower 20% dark and simple. | O7: =Style!$B$5 -> text, letters, words, captions, logos, watermark, signature, card frame, border, UI, photorealistic, 3D render, CGI, glossy, airbrushed, smooth digital painting, anime, cartoon, comic-book gore, paint-splatter blood, bright saturated red, daylight, white background, modern clothing, modern objects, blue light, living expression, open smiling eyes | P7: 2:3 | Q7: cemetery-05.png
A8: Cemetery 06 | B8: Cemetery | C8: bones | D8: 0 | E8: 0 | F8: 0 | G8: 5 | H8: =SUM(D8:G8) -> 5 | I8: 0 | J8: 0 | L8: Bones only | M8: A skeleton still wrapped in a rotted shroud, finger bones clutching a tarnished rosary, a few strands of hair and rags of skin still clinging | N8: =M8&". "&Style!$B$3&" "&Style!$B$7 -> A skeleton still wrapped in a rotted shroud, finger bones clutching a tarnished rosary, a few strands of hair and rags of skin still clinging. Dark hand-drawn coloured-pencil illustration on black-toned paper. Visible pencil strokes and dense cross-hatching, waxy layered colour, soft grain of the paper showing through. Gothic 1819 Paris anatomical horror, Mary Shelley mood. Even darker than daylight allows: the body emerges from deep black, lit hard from one side by a single lantern. Visceral and unflinching: decaying flesh built up in waxy layers of grey-green, livid purple, jaundiced yellow and clotted oxblood; raw wounds, torn stitches, split skin, exposed bone and sinew where the body is broken; flies and grave dirt where it fits. Rendered with the cold precision of an anatomist's study, not cartoon splatter. No blue anywhere: these bodies have no spark of life. Hand-made imperfections, no digital gloss. Format: 2:3 portrait, the body seen from above as it lies, head and upper torso, centred, lower 20% dark and simple. | O8: =Style!$B$5 -> text, letters, words, captions, logos, watermark, signature, card frame, border, UI, photorealistic, 3D render, CGI, glossy, airbrushed, smooth digital painting, anime, cartoon, comic-book gore, paint-splatter blood, bright saturated red, daylight, white background, modern clothing, modern objects, blue light, living expression, open smiling eyes | P8: 2:3 | Q8: cemetery-06.png
A9: Cemetery 07 | B9: Cemetery | C9: bones | D9: 0 | E9: 0 | F9: 0 | G9: 4 | H9: =SUM(D9:G9) -> 4 | I9: 0 | J9: 0 | L9: Bones only | M9: A pile of femurs, ribs and vertebrae dumped beside an open grave, soil clinging to them, a few strands of hair and rags of skin still clinging | N9: =M9&". "&Style!$B$3&" "&Style!$B$7 -> A pile of femurs, ribs and vertebrae dumped beside an open grave, soil clinging to them, a few strands of hair and rags of skin still clinging. Dark hand-drawn coloured-pencil illustration on black-toned paper. Visible pencil strokes and dense cross-hatching, waxy layered colour, soft grain of the paper showing through. Gothic 1819 Paris anatomical horror, Mary Shelley mood. Even darker than daylight allows: the body emerges from deep black, lit hard from one side by a single lantern. Visceral and unflinching: decaying flesh built up in waxy layers of grey-green, livid purple, jaundiced yellow and clotted oxblood; raw wounds, torn stitches, split skin, exposed bone and sinew where the body is broken; flies and grave dirt where it fits. Rendered with the cold precision of an anatomist's study, not cartoon splatter. No blue anywhere: these bodies have no spark of life. Hand-made imperfections, no digital gloss. Format: 2:3 portrait, the body seen from above as it lies, head and upper torso, centred, lower 20% dark and simple. | O9: =Style!$B$5 -> text, letters, words, captions, logos, watermark, signature, card frame, border, UI, photorealistic, 3D render, CGI, glossy, airbrushed, smooth digital painting, anime, cartoon, comic-book gore, paint-splatter blood, bright saturated red, daylight, white background, modern clothing, modern objects, blue light, living expression, open smiling eyes | P9: 2:3 | Q9: cemetery-07.png
A10: Cemetery 08 | B10: Cemetery | C10: bones | D10: 0 | E10: 0 | F10: 0 | G10: 4 | H10: =SUM(D10:G10) -> 4 | I10: 0 | J10: 0 | L10: Bones only | M10: A skull and long bones in a broken lead-lined coffin, a corroded name plate beside them, a few strands of hair and rags of skin still clinging | N10: =M10&". "&Style!$B$3&" "&Style!$B$7 -> A skull and long bones in a broken lead-lined coffin, a corroded name plate beside them, a few strands of hair and rags of skin still clinging. Dark hand-drawn coloured-pencil illustration on black-toned paper. Visible pencil strokes and dense cross-hatching, waxy layered colour, soft grain of the paper showing through. Gothic 1819 Paris anatomical horror, Mary Shelley mood. Even darker than daylight allows: the body emerges from deep black, lit hard from one side by a single lantern. Visceral and unflinching: decaying flesh built up in waxy layers of grey-green, livid purple, jaundiced yellow and clotted oxblood; raw wounds, torn stitches, split skin, exposed bone and sinew where the body is broken; flies and grave dirt where it fits. Rendered with the cold precision of an anatomist's study, not cartoon splatter. No blue anywhere: these bodies have no spark of life. Hand-made imperfections, no digital gloss. Format: 2:3 portrait, the body seen from above as it lies, head and upper torso, centred, lower 20% dark and simple. | O10: =Style!$B$5 -> text, letters, words, captions, logos, watermark, signature, card frame, border, UI, photorealistic, 3D render, CGI, glossy, airbrushed, smooth digital painting, anime, cartoon, comic-book gore, paint-splatter blood, bright saturated red, daylight, white background, modern clothing, modern objects, blue light, living expression, open smiling eyes | P10: 2:3 | Q10: cemetery-08.png
A11: Cemetery 09 | B11: Cemetery | C11: III | D11: 3 | E11: 4 | F11: 0 | G11: 3 | H11: =SUM(D11:G11) -> 10 | I11: 1 | J11: 1 | M11: A woman in her thirties, a dried rose still pinned in her hair, cheeks swollen and split, freshly dug up by lantern light, grave dirt and roots around, dead a week, bloated, marbled green veins under the skin, skin slipping at the edges | N11: =M11&". "&Style!$B$3&" "&Style!$B$7 -> A woman in her thirties, a dried rose still pinned in her hair, cheeks swollen and split, freshly dug up by lantern light, grave dirt and roots around, dead a week, bloated, marbled green veins under the skin, skin slipping at the edges. Dark hand-drawn coloured-pencil illustration on black-toned paper. Visible pencil strokes and dense cross-hatching, waxy layered colour, soft grain of the paper showing through. Gothic 1819 Paris anatomical horror, Mary Shelley mood. Even darker than daylight allows: the body emerges from deep black, lit hard from one side by a single lantern. Visceral and unflinching: decaying flesh built up in waxy layers of grey-green, livid purple, jaundiced yellow and clotted oxblood; raw wounds, torn stitches, split skin, exposed bone and sinew where the body is broken; flies and grave dirt where it fits. Rendered with the cold precision of an anatomist's study, not cartoon splatter. No blue anywhere: these bodies have no spark of life. Hand-made imperfections, no digital gloss. Format: 2:3 portrait, the body seen from above as it lies, head and upper torso, centred, lower 20% dark and simple. | O11: =Style!$B$5 -> text, letters, words, captions, logos, watermark, signature, card frame, border, UI, photorealistic, 3D render, CGI, glossy, airbrushed, smooth digital painting, anime, cartoon, comic-book gore, paint-splatter blood, bright saturated red, daylight, white background, modern clothing, modern objects, blue light, living expression, open smiling eyes | P11: 2:3 | Q11: cemetery-09.png
A12: Cemetery 10 | B12: Cemetery | C12: III | D12: 3 | E12: 4 | F12: 0 | G12: 2 | H12: =SUM(D12:G12) -> 9 | I12: 1 | J12: 1 | M12: A grey-bearded Seine sailor, tattooed forearm gone purple-black, cheeks torn, freshly dug up by lantern light, grave dirt and roots around, dead a week, bloated, marbled green veins under the skin, skin slipping at the edges | N12: =M12&". "&Style!$B$3&" "&Style!$B$7 -> A grey-bearded Seine sailor, tattooed forearm gone purple-black, cheeks torn, freshly dug up by lantern light, grave dirt and roots around, dead a week, bloated, marbled green veins under the skin, skin slipping at the edges. Dark hand-drawn coloured-pencil illustration on black-toned paper. Visible pencil strokes and dense cross-hatching, waxy layered colour, soft grain of the paper showing through. Gothic 1819 Paris anatomical horror, Mary Shelley mood. Even darker than daylight allows: the body emerges from deep black, lit hard from one side by a single lantern. Visceral and unflinching: decaying flesh built up in waxy layers of grey-green, livid purple, jaundiced yellow and clotted oxblood; raw wounds, torn stitches, split skin, exposed bone and sinew where the body is broken; flies and grave dirt where it fits. Rendered with the cold precision of an anatomist's study, not cartoon splatter. No blue anywhere: these bodies have no spark of life. Hand-made imperfections, no digital gloss. Format: 2:3 portrait, the body seen from above as it lies, head and upper torso, centred, lower 20% dark and simple. | O12: =Style!$B$5 -> text, letters, words, captions, logos, watermark, signature, card frame, border, UI, photorealistic, 3D render, CGI, glossy, airbrushed, smooth digital painting, anime, cartoon, comic-book gore, paint-splatter blood, bright saturated red, daylight, white background, modern clothing, modern objects, blue light, living expression, open smiling eyes | P12: 2:3 | Q12: cemetery-10.png
A13: Cemetery 11 | B13: Cemetery | C13: III | D13: 3 | E13: 3 | F13: 0 | G13: 2 | H13: =SUM(D13:G13) -> 8 | I13: 1 | J13: 1 | M13: A young man with a rope burn around his neck, face swollen dark, tongue thick between his teeth, freshly dug up by lantern light, grave dirt and roots around, dead a week, bloated, marbled green veins under the skin, skin slipping at the edges | N13: =M13&". "&Style!$B$3&" "&Style!$B$7 -> A young man with a rope burn around his neck, face swollen dark, tongue thick between his teeth, freshly dug up by lantern light, grave dirt and roots around, dead a week, bloated, marbled green veins under the skin, skin slipping at the edges. Dark hand-drawn coloured-pencil illustration on black-toned paper. Visible pencil strokes and dense cross-hatching, waxy layered colour, soft grain of the paper showing through. Gothic 1819 Paris anatomical horror, Mary Shelley mood. Even darker than daylight allows: the body emerges from deep black, lit hard from one side by a single lantern. Visceral and unflinching: decaying flesh built up in waxy layers of grey-green, livid purple, jaundiced yellow and clotted oxblood; raw wounds, torn stitches, split skin, exposed bone and sinew where the body is broken; flies and grave dirt where it fits. Rendered with the cold precision of an anatomist's study, not cartoon splatter. No blue anywhere: these bodies have no spark of life. Hand-made imperfections, no digital gloss. Format: 2:3 portrait, the body seen from above as it lies, head and upper torso, centred, lower 20% dark and simple. | O13: =Style!$B$5 -> text, letters, words, captions, logos, watermark, signature, card frame, border, UI, photorealistic, 3D render, CGI, glossy, airbrushed, smooth digital painting, anime, cartoon, comic-book gore, paint-splatter blood, bright saturated red, daylight, white background, modern clothing, modern objects, blue light, living expression, open smiling eyes | P13: 2:3 | Q13: cemetery-11.png
A14: Cemetery 12 | B14: Cemetery | C14: III | D14: 2 | E14: 3 | F14: 0 | G14: 3 | H14: =SUM(D14:G14) -> 8 | I14: 1 | J14: 1 | M14: A seamstress with needle-scarred fingers, skin waxy and torn at the lips, hair matted with soil, freshly dug up by lantern light, grave dirt and roots around, dead a week, bloated, marbled green veins under the skin, skin slipping at the edges | N14: =M14&". "&Style!$B$3&" "&Style!$B$7 -> A seamstress with needle-scarred fingers, skin waxy and torn at the lips, hair matted with soil, freshly dug up by lantern light, grave dirt and roots around, dead a week, bloated, marbled green veins under the skin, skin slipping at the edges. Dark hand-drawn coloured-pencil illustration on black-toned paper. Visible pencil strokes and dense cross-hatching, waxy layered colour, soft grain of the paper showing through. Gothic 1819 Paris anatomical horror, Mary Shelley mood. Even darker than daylight allows: the body emerges from deep black, lit hard from one side by a single lantern. Visceral and unflinching: decaying flesh built up in waxy layers of grey-green, livid purple, jaundiced yellow and clotted oxblood; raw wounds, torn stitches, split skin, exposed bone and sinew where the body is broken; flies and grave dirt where it fits. Rendered with the cold precision of an anatomist's study, not cartoon splatter. No blue anywhere: these bodies have no spark of life. Hand-made imperfections, no digital gloss. Format: 2:3 portrait, the body seen from above as it lies, head and upper torso, centred, lower 20% dark and simple. | O14: =Style!$B$5 -> text, letters, words, captions, logos, watermark, signature, card frame, border, UI, photorealistic, 3D render, CGI, glossy, airbrushed, smooth digital painting, anime, cartoon, comic-book gore, paint-splatter blood, bright saturated red, daylight, white background, modern clothing, modern objects, blue light, living expression, open smiling eyes | P14: 2:3 | Q14: cemetery-12.png
A15: Cemetery 13 | B15: Cemetery | C15: III | D15: 1 | E15: 2 | F15: 0 | G15: 3 | H15: =SUM(D15:G15) -> 6 | I15: 1 | J15: 0 | M15: A gaunt old priest in a mouldering cassock, flesh shrinking back from the fingernails, freshly dug up by lantern light, grave dirt and roots around, dead a week, bloated, marbled green veins under the skin, skin slipping at the edges | N15: =M15&". "&Style!$B$3&" "&Style!$B$7 -> A gaunt old priest in a mouldering cassock, flesh shrinking back from the fingernails, freshly dug up by lantern light, grave dirt and roots around, dead a week, bloated, marbled green veins under the skin, skin slipping at the edges. Dark hand-drawn coloured-pencil illustration on black-toned paper. Visible pencil strokes and dense cross-hatching, waxy layered colour, soft grain of the paper showing through. Gothic 1819 Paris anatomical horror, Mary Shelley mood. Even darker than daylight allows: the body emerges from deep black, lit hard from one side by a single lantern. Visceral and unflinching: decaying flesh built up in waxy layers of grey-green, livid purple, jaundiced yellow and clotted oxblood; raw wounds, torn stitches, split skin, exposed bone and sinew where the body is broken; flies and grave dirt where it fits. Rendered with the cold precision of an anatomist's study, not cartoon splatter. No blue anywhere: these bodies have no spark of life. Hand-made imperfections, no digital gloss. Format: 2:3 portrait, the body seen from above as it lies, head and upper torso, centred, lower 20% dark and simple. | O15: =Style!$B$5 -> text, letters, words, captions, logos, watermark, signature, card frame, border, UI, photorealistic, 3D render, CGI, glossy, airbrushed, smooth digital painting, anime, cartoon, comic-book gore, paint-splatter blood, bright saturated red, daylight, white background, modern clothing, modern objects, blue light, living expression, open smiling eyes | P15: 2:3 | Q15: cemetery-13.png
A16: Cemetery 14 | B16: Cemetery | C16: IV | D16: 3 | E16: 4 | F16: 0 | G16: 2 | H16: =SUM(D16:G16) -> 9 | I16: 1 | J16: 0 | M16: A corpulent merchant in rotted burial silk, body burst and leaking, rings sunk into swollen fingers, freshly dug up by lantern light, grave dirt and roots around, months in the ground, flesh shrunken and blackened, skin parchment-thin and torn, teeth bared | N16: =M16&". "&Style!$B$3&" "&Style!$B$7 -> A corpulent merchant in rotted burial silk, body burst and leaking, rings sunk into swollen fingers, freshly dug up by lantern light, grave dirt and roots around, months in the ground, flesh shrunken and blackened, skin parchment-thin and torn, teeth bared. Dark hand-drawn coloured-pencil illustration on black-toned paper. Visible pencil strokes and dense cross-hatching, waxy layered colour, soft grain of the paper showing through. Gothic 1819 Paris anatomical horror, Mary Shelley mood. Even darker than daylight allows: the body emerges from deep black, lit hard from one side by a single lantern. Visceral and unflinching: decaying flesh built up in waxy layers of grey-green, livid purple, jaundiced yellow and clotted oxblood; raw wounds, torn stitches, split skin, exposed bone and sinew where the body is broken; flies and grave dirt where it fits. Rendered with the cold precision of an anatomist's study, not cartoon splatter. No blue anywhere: these bodies have no spark of life. Hand-made imperfections, no digital gloss. Format: 2:3 portrait, the body seen from above as it lies, head and upper torso, centred, lower 20% dark and simple. | O16: =Style!$B$5 -> text, letters, words, captions, logos, watermark, signature, card frame, border, UI, photorealistic, 3D render, CGI, glossy, airbrushed, smooth digital painting, anime, cartoon, comic-book gore, paint-splatter blood, bright saturated red, daylight, white background, modern clothing, modern objects, blue light, living expression, open smiling eyes | P16: 2:3 | Q16: cemetery-14.png
A17: Hospital 01 | B17: Hospital | C17: II | D17: 2 | E17: 3 | F17: 1 | G17: 2 | H17: =SUM(D17:G17) -> 8 | I17: 1 | J17: 0 | M17: An old woman with a fever-ravaged face, a blood-soaked bandage around her throat, eye swollen shut, lying on a stained hospital pillow under coarse linen, dead a day or two, lividity pooling purple, lips greying | N17: =M17&". "&Style!$B$3&" "&Style!$B$7 -> An old woman with a fever-ravaged face, a blood-soaked bandage around her throat, eye swollen shut, lying on a stained hospital pillow under coarse linen, dead a day or two, lividity pooling purple, lips greying. Dark hand-drawn coloured-pencil illustration on black-toned paper. Visible pencil strokes and dense cross-hatching, waxy layered colour, soft grain of the paper showing through. Gothic 1819 Paris anatomical horror, Mary Shelley mood. Even darker than daylight allows: the body emerges from deep black, lit hard from one side by a single lantern. Visceral and unflinching: decaying flesh built up in waxy layers of grey-green, livid purple, jaundiced yellow and clotted oxblood; raw wounds, torn stitches, split skin, exposed bone and sinew where the body is broken; flies and grave dirt where it fits. Rendered with the cold precision of an anatomist's study, not cartoon splatter. No blue anywhere: these bodies have no spark of life. Hand-made imperfections, no digital gloss. Format: 2:3 portrait, the body seen from above as it lies, head and upper torso, centred, lower 20% dark and simple. | O17: =Style!$B$5 -> text, letters, words, captions, logos, watermark, signature, card frame, border, UI, photorealistic, 3D render, CGI, glossy, airbrushed, smooth digital painting, anime, cartoon, comic-book gore, paint-splatter blood, bright saturated red, daylight, white background, modern clothing, modern objects, blue light, living expression, open smiling eyes | P17: 2:3 | Q17: hospital-01.png
A18: Hospital 02 | B18: Hospital | C18: II | D18: 3 | E18: 2 | F18: 1 | G18: 2 | H18: =SUM(D18:G18) -> 8 | I18: 1 | J18: 0 | M18: A moustached porter with a surgical saw wound across his shoulder, sutures torn open, lying on a stained hospital pillow under coarse linen, dead a day or two, lividity pooling purple, lips greying | N18: =M18&". "&Style!$B$3&" "&Style!$B$7 -> A moustached porter with a surgical saw wound across his shoulder, sutures torn open, lying on a stained hospital pillow under coarse linen, dead a day or two, lividity pooling purple, lips greying. Dark hand-drawn coloured-pencil illustration on black-toned paper. Visible pencil strokes and dense cross-hatching, waxy layered colour, soft grain of the paper showing through. Gothic 1819 Paris anatomical horror, Mary Shelley mood. Even darker than daylight allows: the body emerges from deep black, lit hard from one side by a single lantern. Visceral and unflinching: decaying flesh built up in waxy layers of grey-green, livid purple, jaundiced yellow and clotted oxblood; raw wounds, torn stitches, split skin, exposed bone and sinew where the body is broken; flies and grave dirt where it fits. Rendered with the cold precision of an anatomist's study, not cartoon splatter. No blue anywhere: these bodies have no spark of life. Hand-made imperfections, no digital gloss. Format: 2:3 portrait, the body seen from above as it lies, head and upper torso, centred, lower 20% dark and simple. | O18: =Style!$B$5 -> text, letters, words, captions, logos, watermark, signature, card frame, border, UI, photorealistic, 3D render, CGI, glossy, airbrushed, smooth digital painting, anime, cartoon, comic-book gore, paint-splatter blood, bright saturated red, daylight, white background, modern clothing, modern objects, blue light, living expression, open smiling eyes | P18: 2:3 | Q18: hospital-02.png
A19: Hospital 03 | B19: Hospital | C19: II | D19: 2 | E19: 2 | F19: 1 | G19: 3 | H19: =SUM(D19:G19) -> 8 | I19: 1 | J19: 0 | M19: A young clerk with a bullet wound at the temple, a crust of blood down his cheek, lying on a stained hospital pillow under coarse linen, dead a day or two, lividity pooling purple, lips greying | N19: =M19&". "&Style!$B$3&" "&Style!$B$7 -> A young clerk with a bullet wound at the temple, a crust of blood down his cheek, lying on a stained hospital pillow under coarse linen, dead a day or two, lividity pooling purple, lips greying. Dark hand-drawn coloured-pencil illustration on black-toned paper. Visible pencil strokes and dense cross-hatching, waxy layered colour, soft grain of the paper showing through. Gothic 1819 Paris anatomical horror, Mary Shelley mood. Even darker than daylight allows: the body emerges from deep black, lit hard from one side by a single lantern. Visceral and unflinching: decaying flesh built up in waxy layers of grey-green, livid purple, jaundiced yellow and clotted oxblood; raw wounds, torn stitches, split skin, exposed bone and sinew where the body is broken; flies and grave dirt where it fits. Rendered with the cold precision of an anatomist's study, not cartoon splatter. No blue anywhere: these bodies have no spark of life. Hand-made imperfections, no digital gloss. Format: 2:3 portrait, the body seen from above as it lies, head and upper torso, centred, lower 20% dark and simple. | O19: =Style!$B$5 -> text, letters, words, captions, logos, watermark, signature, card frame, border, UI, photorealistic, 3D render, CGI, glossy, airbrushed, smooth digital painting, anime, cartoon, comic-book gore, paint-splatter blood, bright saturated red, daylight, white background, modern clothing, modern objects, blue light, living expression, open smiling eyes | P19: 2:3 | Q19: hospital-03.png
A20: Hospital 04 | B20: Hospital | C20: II | D20: 1 | E20: 2 | F20: 1 | G20: 1 | H20: =SUM(D20:G20) -> 5 | I20: 1 | J20: 0 | M20: A young woman dead of cholera, skin blue-grey and drawn tight, eyes sunken, lying on a stained hospital pillow under coarse linen, dead a day or two, lividity pooling purple, lips greying | N20: =M20&". "&Style!$B$3&" "&Style!$B$7 -> A young woman dead of cholera, skin blue-grey and drawn tight, eyes sunken, lying on a stained hospital pillow under coarse linen, dead a day or two, lividity pooling purple, lips greying. Dark hand-drawn coloured-pencil illustration on black-toned paper. Visible pencil strokes and dense cross-hatching, waxy layered colour, soft grain of the paper showing through. Gothic 1819 Paris anatomical horror, Mary Shelley mood. Even darker than daylight allows: the body emerges from deep black, lit hard from one side by a single lantern. Visceral and unflinching: decaying flesh built up in waxy layers of grey-green, livid purple, jaundiced yellow and clotted oxblood; raw wounds, torn stitches, split skin, exposed bone and sinew where the body is broken; flies and grave dirt where it fits. Rendered with the cold precision of an anatomist's study, not cartoon splatter. No blue anywhere: these bodies have no spark of life. Hand-made imperfections, no digital gloss. Format: 2:3 portrait, the body seen from above as it lies, head and upper torso, centred, lower 20% dark and simple. | O20: =Style!$B$5 -> text, letters, words, captions, logos, watermark, signature, card frame, border, UI, photorealistic, 3D render, CGI, glossy, airbrushed, smooth digital painting, anime, cartoon, comic-book gore, paint-splatter blood, bright saturated red, daylight, white background, modern clothing, modern objects, blue light, living expression, open smiling eyes | P20: 2:3 | Q20: hospital-04.png
A21: Hospital 05 | B21: Hospital | C21: I | D21: 2 | E21: 3 | F21: 1 | G21: 3 | H21: =SUM(D21:G21) -> 9 | I21: 2 | J21: 0 | M21: A bald old man with a sunken chest, bruised black where the surgeon’s ribs-spreader went in, lying on a stained hospital pillow under coarse linen, freshly dead, skin still waxy-pale, blood barely dry | N21: =M21&". "&Style!$B$3&" "&Style!$B$7 -> A bald old man with a sunken chest, bruised black where the surgeon’s ribs-spreader went in, lying on a stained hospital pillow under coarse linen, freshly dead, skin still waxy-pale, blood barely dry. Dark hand-drawn coloured-pencil illustration on black-toned paper. Visible pencil strokes and dense cross-hatching, waxy layered colour, soft grain of the paper showing through. Gothic 1819 Paris anatomical horror, Mary Shelley mood. Even darker than daylight allows: the body emerges from deep black, lit hard from one side by a single lantern. Visceral and unflinching: decaying flesh built up in waxy layers of grey-green, livid purple, jaundiced yellow and clotted oxblood; raw wounds, torn stitches, split skin, exposed bone and sinew where the body is broken; flies and grave dirt where it fits. Rendered with the cold precision of an anatomist's study, not cartoon splatter. No blue anywhere: these bodies have no spark of life. Hand-made imperfections, no digital gloss. Format: 2:3 portrait, the body seen from above as it lies, head and upper torso, centred, lower 20% dark and simple. | O21: =Style!$B$5 -> text, letters, words, captions, logos, watermark, signature, card frame, border, UI, photorealistic, 3D render, CGI, glossy, airbrushed, smooth digital painting, anime, cartoon, comic-book gore, paint-splatter blood, bright saturated red, daylight, white background, modern clothing, modern objects, blue light, living expression, open smiling eyes | P21: 2:3 | Q21: hospital-05.png
A22: Hospital 06 | B22: Hospital | C22: I | D22: 3 | E22: 2 | F22: 1 | G22: 3 | H22: =SUM(D22:G22) -> 9 | I22: 2 | J22: 0 | M22: A coal porter with a crushed chest, broken ribs pushing against bloodied linen, lying on a stained hospital pillow under coarse linen, freshly dead, skin still waxy-pale, blood barely dry | N22: =M22&". "&Style!$B$3&" "&Style!$B$7 -> A coal porter with a crushed chest, broken ribs pushing against bloodied linen, lying on a stained hospital pillow under coarse linen, freshly dead, skin still waxy-pale, blood barely dry. Dark hand-drawn coloured-pencil illustration on black-toned paper. Visible pencil strokes and dense cross-hatching, waxy layered colour, soft grain of the paper showing through. Gothic 1819 Paris anatomical horror, Mary Shelley mood. Even darker than daylight allows: the body emerges from deep black, lit hard from one side by a single lantern. Visceral and unflinching: decaying flesh built up in waxy layers of grey-green, livid purple, jaundiced yellow and clotted oxblood; raw wounds, torn stitches, split skin, exposed bone and sinew where the body is broken; flies and grave dirt where it fits. Rendered with the cold precision of an anatomist's study, not cartoon splatter. No blue anywhere: these bodies have no spark of life. Hand-made imperfections, no digital gloss. Format: 2:3 portrait, the body seen from above as it lies, head and upper torso, centred, lower 20% dark and simple. | O22: =Style!$B$5 -> text, letters, words, captions, logos, watermark, signature, card frame, border, UI, photorealistic, 3D render, CGI, glossy, airbrushed, smooth digital painting, anime, cartoon, comic-book gore, paint-splatter blood, bright saturated red, daylight, white background, modern clothing, modern objects, blue light, living expression, open smiling eyes | P22: 2:3 | Q22: hospital-06.png
... A53: Public Square 09 | B53: Public Square | C53: I | D53: 4 | E53: 4 | F53: 3 | G53: 2 | H53: =SUM(D53:G53) -> 13 | I53: 2 | J53: 0 | M53: An executed street thief, very young, the cut neck glistening in the lantern light, dumped on wet cobblestones beside the scaffold, straw soaked dark, freshly dead, skin still waxy-pale, blood barely dry | N53: =M53&". "&Style!$B$3&" "&Style!$B$7 -> An executed street thief, very young, the cut neck glistening in the lantern light, dumped on wet cobblestones beside the scaffold, straw soaked dark, freshly dead, skin still waxy-pale, blood barely dry. Dark hand-drawn coloured-pencil illustration on black-toned paper. Visible pencil strokes and dense cross-hatching, waxy layered colour, soft grain of the paper showing through. Gothic 1819 Paris anatomical horror, Mary Shelley mood. Even darker than daylight allows: the body emerges from deep black, lit hard from one side by a single lantern. Visceral and unflinching: decaying flesh built up in waxy layers of grey-green, livid purple, jaundiced yellow and clotted oxblood; raw wounds, torn stitches, split skin, exposed bone and sinew where the body is broken; flies and grave dirt where it fits. Rendered with the cold precision of an anatomist's study, not cartoon splatter. No blue anywhere: these bodies have no spark of life. Hand-made imperfections, no digital gloss. Format: 2:3 portrait, the body seen from above as it lies, head and upper torso, centred, lower 20% dark and simple. | O53: =Style!$B$5 -> text, letters, words, captions, logos, watermark, signature, card frame, border, UI, photorealistic, 3D render, CGI, glossy, airbrushed, smooth digital painting, anime, cartoon, comic-book gore, paint-splatter blood, bright saturated red, daylight, white background, modern clothing, modern objects, blue light, living expression, open smiling eyes | P53: 2:3 | Q53: square-09.png
A54: Public Square 10 | B54: Public Square | C54: I | D54: 4 | E54: 4 | F54: 4 | G54: 4 | H54: =SUM(D54:G54) -> 16 | I54: 3 | J54: 0 | K54: 1 | L54: Big Gustave, the butcher of Rungis | M54: Big Gustave the butcher of Rungis, executed, an enormous man with a vast slack face, the blade wound across a thick neck, dumped on wet cobblestones beside the scaffold, straw soaked dark, freshly dead, skin still waxy-pale, blood barely dry | N54: =M54&". "&Style!$B$3&" "&Style!$B$7 -> Big Gustave the butcher of Rungis, executed, an enormous man with a vast slack face, the blade wound across a thick neck, dumped on wet cobblestones beside the scaffold, straw soaked dark, freshly dead, skin still waxy-pale, blood barely dry. Dark hand-drawn coloured-pencil illustration on black-toned paper. Visible pencil strokes and dense cross-hatching, waxy layered colour, soft grain of the paper showing through. Gothic 1819 Paris anatomical horror, Mary Shelley mood. Even darker than daylight allows: the body emerges from deep black, lit hard from one side by a single lantern. Visceral and unflinching: decaying flesh built up in waxy layers of grey-green, livid purple, jaundiced yellow and clotted oxblood; raw wounds, torn stitches, split skin, exposed bone and sinew where the body is broken; flies and grave dirt where it fits. Rendered with the cold precision of an anatomist's study, not cartoon splatter. No blue anywhere: these bodies have no spark of life. Hand-made imperfections, no digital gloss. Format: 2:3 portrait, the body seen from above as it lies, head and upper torso, centred, lower 20% dark and simple. | O54: =Style!$B$5 -> text, letters, words, captions, logos, watermark, signature, card frame, border, UI, photorealistic, 3D render, CGI, glossy, airbrushed, smooth digital painting, anime, cartoon, comic-book gore, paint-splatter blood, bright saturated red, daylight, white background, modern clothing, modern objects, blue light, living expression, open smiling eyes | P54: 2:3 | Q54: square-10.png

Sheet Scoundrels
A1: Numbers follow the physical game (read from the Tabletop Simulator sheets). Names, wording and art are original to The Second Spark.
A2: Card | B2: Name | C2: Cost (f) | D2: Humanity cost | E2: Materials option | F2: Expertise option | G2: Humanity option | H2: Illustration subject | I2: Prompt (ready to paste) | J2: Negative prompt | K2: Aspect | L2: File name
A3: Scoundrel 01 | B3: Hospital Thief | C3: 2 | D3: 1 | E3: Draw 2 Hospital bodies and resolve | H3: A hulking hospital porter with a black beard carrying a sheet-wrapped corpse over his shoulder | I3: =H3&". "&Style!$B$2&" "&Style!$B$6 -> A hulking hospital porter with a black beard carrying a sheet-wrapped corpse over his shoulder. Dark hand-drawn coloured-pencil illustration on black-toned paper. Visible pencil strokes and cross-hatching, waxy layered colour, soft grain of the paper showing through. Gothic 1819 Paris, Mary Shelley mood. Low-key candlelit lighting: a single warm light source (candle, lantern or lamp) carving figures out of near-black shadow. Muted palette of soot black, bruised plum, oxblood red, tarnished brass and bone white, with one small accent of cold galvanic blue where electricity or life appears. Subtle vignette fading to black at the edges. Melancholic, unsettling, quietly beautiful rather than gory: wounds and death are suggested with restraint, never graphic. Hand-made imperfections, no digital gloss. Format: 2:3 portrait, head and shoulders, centred, lower 20% dark and simple. | J3: =Style!$B$4 -> text, letters, words, captions, logos, watermark, signature, card frame, border, UI, photorealistic, 3D render, CGI, glossy, airbrushed, smooth digital painting, anime, cartoon, chibi, bright saturated colours, daylight, white background, gore, exposed organs in detail, modern clothing, modern objects | K3: 2:3 | L3: scoundrel-01.png
A4: Scoundrel 02 | B4: Hospital Thief | C4: 2 | D4: 1 | E4: Draw 2 Hospital bodies and resolve | H4: A hard-faced nurse in a stained apron and cap, a covered trolley behind her | I4: =H4&". "&Style!$B$2&" "&Style!$B$6 -> A hard-faced nurse in a stained apron and cap, a covered trolley behind her. Dark hand-drawn coloured-pencil illustration on black-toned paper. Visible pencil strokes and cross-hatching, waxy layered colour, soft grain of the paper showing through. Gothic 1819 Paris, Mary Shelley mood. Low-key candlelit lighting: a single warm light source (candle, lantern or lamp) carving figures out of near-black shadow. Muted palette of soot black, bruised plum, oxblood red, tarnished brass and bone white, with one small accent of cold galvanic blue where electricity or life appears. Subtle vignette fading to black at the edges. Melancholic, unsettling, quietly beautiful rather than gory: wounds and death are suggested with restraint, never graphic. Hand-made imperfections, no digital gloss. Format: 2:3 portrait, head and shoulders, centred, lower 20% dark and simple. | J4: =Style!$B$4 -> text, letters, words, captions, logos, watermark, signature, card frame, border, UI, photorealistic, 3D render, CGI, glossy, airbrushed, smooth digital painting, anime, cartoon, chibi, bright saturated colours, daylight, white background, gore, exposed organs in detail, modern clothing, modern objects | K4: 2:3 | L4: scoundrel-02.png
A5: Scoundrel 03 | B5: Hospital Thief | C5: 1 | D5: 1 | E5: Draw 1 Hospital body and resolve | H5: A sly hospital orderly with a ring of keys, a sheet-covered trolley behind him | I5: =H5&". "&Style!$B$2&" "&Style!$B$6 -> A sly hospital orderly with a ring of keys, a sheet-covered trolley behind him. Dark hand-drawn coloured-pencil illustration on black-toned paper. Visible pencil strokes and cross-hatching, waxy layered colour, soft grain of the paper showing through. Gothic 1819 Paris, Mary Shelley mood. Low-key candlelit lighting: a single warm light source (candle, lantern or lamp) carving figures out of near-black shadow. Muted palette of soot black, bruised plum, oxblood red, tarnished brass and bone white, with one small accent of cold galvanic blue where electricity or life appears. Subtle vignette fading to black at the edges. Melancholic, unsettling, quietly beautiful rather than gory: wounds and death are suggested with restraint, never graphic. Hand-made imperfections, no digital gloss. Format: 2:3 portrait, head and shoulders, centred, lower 20% dark and simple. | J5: =Style!$B$4 -> text, letters, words, captions, logos, watermark, signature, card frame, border, UI, photorealistic, 3D render, CGI, glossy, airbrushed, smooth digital painting, anime, cartoon, chibi, bright saturated colours, daylight, white background, gore, exposed organs in detail, modern clothing, modern objects | K5: 2:3 | L5: scoundrel-03.png
A6: Scoundrel 04 | B6: Hospital Thief | C6: 1 | D6: 1 | E6: Draw 1 Hospital body and resolve | H6: A pale girl with bloody sleeves pushing a trolley under a dirty sheet | I6: =H6&". "&Style!$B$2&" "&Style!$B$6 -> A pale girl with bloody sleeves pushing a trolley under a dirty sheet. Dark hand-drawn coloured-pencil illustration on black-toned paper. Visible pencil strokes and cross-hatching, waxy layered colour, soft grain of the paper showing through. Gothic 1819 Paris, Mary Shelley mood. Low-key candlelit lighting: a single warm light source (candle, lantern or lamp) carving figures out of near-black shadow. Muted palette of soot black, bruised plum, oxblood red, tarnished brass and bone white, with one small accent of cold galvanic blue where electricity or life appears. Subtle vignette fading to black at the edges. Melancholic, unsettling, quietly beautiful rather than gory: wounds and death are suggested with restraint, never graphic. Hand-made imperfections, no digital gloss. Format: 2:3 portrait, head and shoulders, centred, lower 20% dark and simple. | J6: =Style!$B$4 -> text, letters, words, captions, logos, watermark, signature, card frame, border, UI, photorealistic, 3D render, CGI, glossy, airbrushed, smooth digital painting, anime, cartoon, chibi, bright saturated colours, daylight, white background, gore, exposed organs in detail, modern clothing, modern objects | K6: 2:3 | L6: scoundrel-04.png
A7: Scoundrel 05 | B7: Dog Catcher | C7: 2 | D7: 1 | E7: 8 animal (I) | F7: +3 (-1 humanity) | G7: +5 | H7: A dog catcher in a ragged hat and coat with a long net pole, a cage of strays behind | I7: =H7&". "&Style!$B$2&" "&Style!$B$6 -> A dog catcher in a ragged hat and coat with a long net pole, a cage of strays behind. Dark hand-drawn coloured-pencil illustration on black-toned paper. Visible pencil strokes and cross-hatching, waxy layered colour, soft grain of the paper showing through. Gothic 1819 Paris, Mary Shelley mood. Low-key candlelit lighting: a single warm light source (candle, lantern or lamp) carving figures out of near-black shadow. Muted palette of soot black, bruised plum, oxblood red, tarnished brass and bone white, with one small accent of cold galvanic blue where electricity or life appears. Subtle vignette fading to black at the edges. Melancholic, unsettling, quietly beautiful rather than gory: wounds and death are suggested with restraint, never graphic. Hand-made imperfections, no digital gloss. Format: 2:3 portrait, head and shoulders, centred, lower 20% dark and simple. | J7: =Style!$B$4 -> text, letters, words, captions, logos, watermark, signature, card frame, border, UI, photorealistic, 3D render, CGI, glossy, airbrushed, smooth digital painting, anime, cartoon, chibi, bright saturated colours, daylight, white background, gore, exposed organs in detail, modern clothing, modern objects | K7: 2:3 | L7: scoundrel-05.png
A8: Scoundrel 06 | B8: Dog Catcher | C8: 1 | E8: 5 animal (I) | F8: +2 (-1 humanity) | G8: +3 | H8: A heavy old dog catcher with a coil of rope and a muzzle pole, his cart behind him | I8: =H8&". "&Style!$B$2&" "&Style!$B$6 -> A heavy old dog catcher with a coil of rope and a muzzle pole, his cart behind him. Dark hand-drawn coloured-pencil illustration on black-toned paper. Visible pencil strokes and cross-hatching, waxy layered colour, soft grain of the paper showing through. Gothic 1819 Paris, Mary Shelley mood. Low-key candlelit lighting: a single warm light source (candle, lantern or lamp) carving figures out of near-black shadow. Muted palette of soot black, bruised plum, oxblood red, tarnished brass and bone white, with one small accent of cold galvanic blue where electricity or life appears. Subtle vignette fading to black at the edges. Melancholic, unsettling, quietly beautiful rather than gory: wounds and death are suggested with restraint, never graphic. Hand-made imperfections, no digital gloss. Format: 2:3 portrait, head and shoulders, centred, lower 20% dark and simple. | J8: =Style!$B$4 -> text, letters, words, captions, logos, watermark, signature, card frame, border, UI, photorealistic, 3D render, CGI, glossy, airbrushed, smooth digital painting, anime, cartoon, chibi, bright saturated colours, daylight, white background, gore, exposed organs in detail, modern clothing, modern objects | K8: 2:3 | L8: scoundrel-06.png
A9: Scoundrel 07 | B9: Dog Catcher | C9: 1 | E9: 4 animal (I) | F9: +2 (-1 humanity) | G9: +3 | H9: A sharp-faced young woman with a black fringe holding a muzzle pole | I9: =H9&". "&Style!$B$2&" "&Style!$B$6 -> A sharp-faced young woman with a black fringe holding a muzzle pole. Dark hand-drawn coloured-pencil illustration on black-toned paper. Visible pencil strokes and cross-hatching, waxy layered colour, soft grain of the paper showing through. Gothic 1819 Paris, Mary Shelley mood. Low-key candlelit lighting: a single warm light source (candle, lantern or lamp) carving figures out of near-black shadow. Muted palette of soot black, bruised plum, oxblood red, tarnished brass and bone white, with one small accent of cold galvanic blue where electricity or life appears. Subtle vignette fading to black at the edges. Melancholic, unsettling, quietly beautiful rather than gory: wounds and death are suggested with restraint, never graphic. Hand-made imperfections, no digital gloss. Format: 2:3 portrait, head and shoulders, centred, lower 20% dark and simple. | J9: =Style!$B$4 -> text, letters, words, captions, logos, watermark, signature, card frame, border, UI, photorealistic, 3D render, CGI, glossy, airbrushed, smooth digital painting, anime, cartoon, chibi, bright saturated colours, daylight, white background, gore, exposed organs in detail, modern clothing, modern objects | K9: 2:3 | L9: scoundrel-07.png
A10: Scoundrel 08 | B10: Dog Catcher | C10: 1 | E10: 4 animal (I) | F10: +2 (-1 humanity) | G10: +3 | H10: A boy in a feathered hat and green coat with a snare noose | I10: =H10&". "&Style!$B$2&" "&Style!$B$6 -> A boy in a feathered hat and green coat with a snare noose. Dark hand-drawn coloured-pencil illustration on black-toned paper. Visible pencil strokes and cross-hatching, waxy layered colour, soft grain of the paper showing through. Gothic 1819 Paris, Mary Shelley mood. Low-key candlelit lighting: a single warm light source (candle, lantern or lamp) carving figures out of near-black shadow. Muted palette of soot black, bruised plum, oxblood red, tarnished brass and bone white, with one small accent of cold galvanic blue where electricity or life appears. Subtle vignette fading to black at the edges. Melancholic, unsettling, quietly beautiful rather than gory: wounds and death are suggested with restraint, never graphic. Hand-made imperfections, no digital gloss. Format: 2:3 portrait, head and shoulders, centred, lower 20% dark and simple. | J10: =Style!$B$4 -> text, letters, words, captions, logos, watermark, signature, card frame, border, UI, photorealistic, 3D render, CGI, glossy, airbrushed, smooth digital painting, anime, cartoon, chibi, bright saturated colours, daylight, white background, gore, exposed organs in detail, modern clothing, modern objects | K10: 2:3 | L10: scoundrel-08.png
A11: Scoundrel 09 | B11: Cutthroat | C11: 2 | D11: 1 | E11: 4 muscle (I), 4 organ (I), 4 blood (I), 3 bone | F11: +2 | H11: A smiling gentleman in a dark coat, a thin knife glinting in his gloved hand | I11: =H11&". "&Style!$B$2&" "&Style!$B$6 -> A smiling gentleman in a dark coat, a thin knife glinting in his gloved hand. Dark hand-drawn coloured-pencil illustration on black-toned paper. Visible pencil strokes and cross-hatching, waxy layered colour, soft grain of the paper showing through. Gothic 1819 Paris, Mary Shelley mood. Low-key candlelit lighting: a single warm light source (candle, lantern or lamp) carving figures out of near-black shadow. Muted palette of soot black, bruised plum, oxblood red, tarnished brass and bone white, with one small accent of cold galvanic blue where electricity or life appears. Subtle vignette fading to black at the edges. Melancholic, unsettling, quietly beautiful rather than gory: wounds and death are suggested with restraint, never graphic. Hand-made imperfections, no digital gloss. Format: 2:3 portrait, head and shoulders, centred, lower 20% dark and simple. | J11: =Style!$B$4 -> text, letters, words, captions, logos, watermark, signature, card frame, border, UI, photorealistic, 3D render, CGI, glossy, airbrushed, smooth digital painting, anime, cartoon, chibi, bright saturated colours, daylight, white background, gore, exposed organs in detail, modern clothing, modern objects | K11: 2:3 | L11: scoundrel-09.png
